[2025-06-23 12:45:04,340] 51 Common_Utils - CRITICAL - Unhandled Exception
Traceback (most recent call last):
  File "D:\ml_churn_prediction_mlops\src\Experiment_Tracking_Prediction.py", line 21, in <module>
    from Common_Utils import (
ImportError: cannot import name 'setup_logger' from 'Common_Utils' (C:\Users\prasa\anaconda3\Lib\site-packages\Common_Utils\__init__.py)
