[2025-06-21 22:35:29,465] 123 __init__.py - INFO - Loaded config from Config_Yaml/classifiers.yaml
[2025-06-21 22:35:29,681] 123 __init__.py - INFO - Loaded config from Config_Yaml/config_path.yaml
[2025-06-21 22:35:29,681] 100 __init__.py - INFO - Running 'execute_model_tune_evaluate'...
[2025-06-21 22:35:29,681] 221 Model_Tune_Evaluate.py - INFO - Starting Classification Model Tuning...
[2025-06-21 22:35:29,746] 100 __init__.py - INFO - Running 'run_grid_search'...
[2025-06-21 22:35:29,769] 125 Model_Tune_Evaluate.py - INFO - Running Bayesian search for: logistic_regression
[2025-06-21 22:35:29,781] 130 Model_Tune_Evaluate.py - INFO - Starting Feature Engineering..
[2025-06-21 22:35:29,782] 134 Model_Tune_Evaluate.py - INFO - Feature selector and extractor initialized..
[2025-06-21 22:38:17,773] 139 Model_Tune_Evaluate.py - INFO - Feature Engineering completed..
[2025-06-21 22:38:17,773] 142 Model_Tune_Evaluate.py - INFO - Starting model tuning..
[2025-06-21 22:38:38,521] 159 Model_Tune_Evaluate.py - INFO - initial model tuning finished..
[2025-06-21 22:38:38,522] 162 Model_Tune_Evaluate.py - INFO - Starting model fine tuning on (train+val)..
[2025-06-21 22:38:38,524] 194 Model_Tune_Evaluate.py - ERROR - Bayesian search failed.
Traceback (most recent call last):
  File "D:\ml_churn_prediction_mlops\src\Model_Tune_Evaluate.py", line 163, in run_grid_search
    X_val_selected = selector.transform(self.X_val)
  File "d:\ml_churn_prediction_mlops\Model_Utils\feature_selection_extraction.py", line 60, in transform
    X_new = self.selector.transform(X)
  File "C:\Users\prasa\anaconda3\envs\mlp-env\lib\site-packages\sklearn\utils\_set_output.py", line 319, in wrapped
    data_to_wrap = f(self, X, *args, **kwargs)
  File "C:\Users\prasa\anaconda3\envs\mlp-env\lib\site-packages\sklearn\feature_selection\_base.py", line 107, in transform
    X = validate_data(
  File "C:\Users\prasa\anaconda3\envs\mlp-env\lib\site-packages\sklearn\utils\validation.py", line 2919, in validate_data
    _check_feature_names(_estimator, X, reset=reset)
  File "C:\Users\prasa\anaconda3\envs\mlp-env\lib\site-packages\sklearn\utils\validation.py", line 2777, in _check_feature_names
    raise ValueError(message)
ValueError: The feature names should match those that were passed during fit.
Feature names seen at fit time, yet now missing:
- ohe__Marital_Status_Divorced
- ord__Education_Level
- ord__Income_Category

[2025-06-21 22:38:38,537] 227 Model_Tune_Evaluate.py - CRITICAL - Fatal error in classifier tuning pipeline.
[2025-06-21 22:38:38,538] 90 __init__.py - CRITICAL - Unhandled Exception
Traceback (most recent call last):
  File "D:\ml_churn_prediction_mlops\src\Model_Tune_Evaluate.py", line 163, in run_grid_search
    X_val_selected = selector.transform(self.X_val)
  File "d:\ml_churn_prediction_mlops\Model_Utils\feature_selection_extraction.py", line 60, in transform
    X_new = self.selector.transform(X)
  File "C:\Users\prasa\anaconda3\envs\mlp-env\lib\site-packages\sklearn\utils\_set_output.py", line 319, in wrapped
    data_to_wrap = f(self, X, *args, **kwargs)
  File "C:\Users\prasa\anaconda3\envs\mlp-env\lib\site-packages\sklearn\feature_selection\_base.py", line 107, in transform
    X = validate_data(
  File "C:\Users\prasa\anaconda3\envs\mlp-env\lib\site-packages\sklearn\utils\validation.py", line 2919, in validate_data
    _check_feature_names(_estimator, X, reset=reset)
  File "C:\Users\prasa\anaconda3\envs\mlp-env\lib\site-packages\sklearn\utils\validation.py", line 2777, in _check_feature_names
    raise ValueError(message)
ValueError: The feature names should match those that were passed during fit.
Feature names seen at fit time, yet now missing:
- ohe__Marital_Status_Divorced
- ord__Education_Level
- ord__Income_Category


During handling of the above exception, another exception occurred:

Traceback (most recent call last):
  File "D:\ml_churn_prediction_mlops\src\Model_Tune_Evaluate.py", line 223, in execute_model_tune_evaluate
    tuner.run_grid_search()
  File "d:\ml_churn_prediction_mlops\Common_Utils\__init__.py", line 105, in wrapper
    result = func(*args, **kwargs)
  File "D:\ml_churn_prediction_mlops\src\Model_Tune_Evaluate.py", line 195, in run_grid_search
    raise CustomException(e, sys)
Common_Utils.CustomException: Error in script: [D:\ml_churn_prediction_mlops\src\Model_Tune_Evaluate.py] at line [163] - Message: [The feature names should match those that were passed during fit.
Feature names seen at fit time, yet now missing:
- ohe__Marital_Status_Divorced
- ord__Education_Level
- ord__Income_Category
]

During handling of the above exception, another exception occurred:

Traceback (most recent call last):
  File "D:\ml_churn_prediction_mlops\src\Model_Tune_Evaluate.py", line 232, in <module>
    execute_model_tune_evaluate()
  File "d:\ml_churn_prediction_mlops\Common_Utils\__init__.py", line 105, in wrapper
    result = func(*args, **kwargs)
  File "D:\ml_churn_prediction_mlops\src\Model_Tune_Evaluate.py", line 228, in execute_model_tune_evaluate
    raise CustomException(e, sys)
Common_Utils.CustomException: Error in script: [D:\ml_churn_prediction_mlops\src\Model_Tune_Evaluate.py] at line [223] - Message: [Error in script: [D:\ml_churn_prediction_mlops\src\Model_Tune_Evaluate.py] at line [163] - Message: [The feature names should match those that were passed during fit.
Feature names seen at fit time, yet now missing:
- ohe__Marital_Status_Divorced
- ord__Education_Level
- ord__Income_Category
]]
