[2025-06-22 13:21:25,346] 123 __init__.py - INFO - Loaded config from Config_Yaml/classifiers.yaml
[2025-06-22 13:21:25,612] 123 __init__.py - INFO - Loaded config from Config_Yaml/config_path.yaml
[2025-06-22 13:21:25,612] 100 __init__.py - INFO - Running 'execute_model_tune_evaluate'...
[2025-06-22 13:21:25,612] 142 Model_Tune_Evaluate.py - INFO - Starting Classification Model Tuning...
[2025-06-22 13:21:25,689] 100 __init__.py - INFO - Running 'run_grid_search'...
[2025-06-22 13:21:25,707] 123 __init__.py - INFO - Loaded config from Config_Yaml\classifiers.yaml
[2025-06-22 13:21:30,592] 126 Model_Tune_Evaluate.py - ERROR - Bayesian search failed.
Traceback (most recent call last):
  File "D:\ml_churn_prediction_mlops\src\Model_Tune_Evaluate.py", line 90, in run_grid_search
    X_selected = selector.fit_transform(X_sampled, y_sampled)
  File "d:\ml_churn_prediction_mlops\Model_Utils\feature_selection_extraction.py", line 57, in fit_transform
    return self.transform(X)
  File "d:\ml_churn_prediction_mlops\Model_Utils\feature_selection_extraction.py", line 52, in transform
    return pd.DataFrame(self.selector.transform(X[self.selected_columns]),
  File "C:\Users\prasa\anaconda3\envs\mlp-env\lib\site-packages\sklearn\utils\_set_output.py", line 319, in wrapped
    data_to_wrap = f(self, X, *args, **kwargs)
  File "C:\Users\prasa\anaconda3\envs\mlp-env\lib\site-packages\sklearn\feature_selection\_base.py", line 107, in transform
    X = validate_data(
  File "C:\Users\prasa\anaconda3\envs\mlp-env\lib\site-packages\sklearn\utils\validation.py", line 2919, in validate_data
    _check_feature_names(_estimator, X, reset=reset)
  File "C:\Users\prasa\anaconda3\envs\mlp-env\lib\site-packages\sklearn\utils\validation.py", line 2777, in _check_feature_names
    raise ValueError(message)
ValueError: The feature names should match those that were passed during fit.
Feature names seen at fit time, yet now missing:
- ohe__Marital_Status_Divorced
- ohe__Marital_Status_Unknown
- ord__Income_Category

[2025-06-22 13:21:30,608] 148 Model_Tune_Evaluate.py - CRITICAL - Fatal error in tuning pipeline.
[2025-06-22 13:21:30,608] 90 __init__.py - CRITICAL - Unhandled Exception
Traceback (most recent call last):
  File "D:\ml_churn_prediction_mlops\src\Model_Tune_Evaluate.py", line 90, in run_grid_search
    X_selected = selector.fit_transform(X_sampled, y_sampled)
  File "d:\ml_churn_prediction_mlops\Model_Utils\feature_selection_extraction.py", line 57, in fit_transform
    return self.transform(X)
  File "d:\ml_churn_prediction_mlops\Model_Utils\feature_selection_extraction.py", line 52, in transform
    return pd.DataFrame(self.selector.transform(X[self.selected_columns]),
  File "C:\Users\prasa\anaconda3\envs\mlp-env\lib\site-packages\sklearn\utils\_set_output.py", line 319, in wrapped
    data_to_wrap = f(self, X, *args, **kwargs)
  File "C:\Users\prasa\anaconda3\envs\mlp-env\lib\site-packages\sklearn\feature_selection\_base.py", line 107, in transform
    X = validate_data(
  File "C:\Users\prasa\anaconda3\envs\mlp-env\lib\site-packages\sklearn\utils\validation.py", line 2919, in validate_data
    _check_feature_names(_estimator, X, reset=reset)
  File "C:\Users\prasa\anaconda3\envs\mlp-env\lib\site-packages\sklearn\utils\validation.py", line 2777, in _check_feature_names
    raise ValueError(message)
ValueError: The feature names should match those that were passed during fit.
Feature names seen at fit time, yet now missing:
- ohe__Marital_Status_Divorced
- ohe__Marital_Status_Unknown
- ord__Income_Category


During handling of the above exception, another exception occurred:

Traceback (most recent call last):
  File "D:\ml_churn_prediction_mlops\src\Model_Tune_Evaluate.py", line 144, in execute_model_tune_evaluate
    tuner.run_grid_search()
  File "d:\ml_churn_prediction_mlops\Common_Utils\__init__.py", line 105, in wrapper
    result = func(*args, **kwargs)
  File "D:\ml_churn_prediction_mlops\src\Model_Tune_Evaluate.py", line 127, in run_grid_search
    raise CustomException(e, sys)
Common_Utils.CustomException: Error in script: [D:\ml_churn_prediction_mlops\src\Model_Tune_Evaluate.py] at line [90] - Message: [The feature names should match those that were passed during fit.
Feature names seen at fit time, yet now missing:
- ohe__Marital_Status_Divorced
- ohe__Marital_Status_Unknown
- ord__Income_Category
]

During handling of the above exception, another exception occurred:

Traceback (most recent call last):
  File "D:\ml_churn_prediction_mlops\src\Model_Tune_Evaluate.py", line 152, in <module>
    execute_model_tune_evaluate()
  File "d:\ml_churn_prediction_mlops\Common_Utils\__init__.py", line 105, in wrapper
    result = func(*args, **kwargs)
  File "D:\ml_churn_prediction_mlops\src\Model_Tune_Evaluate.py", line 149, in execute_model_tune_evaluate
    raise CustomException(e, sys)
Common_Utils.CustomException: Error in script: [D:\ml_churn_prediction_mlops\src\Model_Tune_Evaluate.py] at line [144] - Message: [Error in script: [D:\ml_churn_prediction_mlops\src\Model_Tune_Evaluate.py] at line [90] - Message: [The feature names should match those that were passed during fit.
Feature names seen at fit time, yet now missing:
- ohe__Marital_Status_Divorced
- ohe__Marital_Status_Unknown
- ord__Income_Category
]]
