[2025-06-21 19:21:33,598] 123 __init__.py - INFO - Loaded config from Config_Yaml/classifiers.yaml
[2025-06-21 19:21:33,926] 123 __init__.py - INFO - Loaded config from Config_Yaml/config_path.yaml
[2025-06-21 19:21:33,926] 100 __init__.py - INFO - Running 'execute_model_tune_evaluate'...
[2025-06-21 19:21:33,926] 189 Model_Tune_Evaluate.py - INFO - Starting Classification Model Tuning...
[2025-06-21 19:21:34,047] 100 __init__.py - INFO - Running 'run_grid_search'...
[2025-06-21 19:21:34,080] 112 Model_Tune_Evaluate.py - INFO - Running grid search for: logistic_regression
[2025-06-21 19:21:41,449] 162 Model_Tune_Evaluate.py - ERROR - Grid search failed.
Traceback (most recent call last):
  File "D:\ml_churn_prediction_mlops\src\Model_Tune_Evaluate.py", line 128, in run_grid_search
    X_selected = selector.fit_transform(X_resampled, y_resampled)
AttributeError: 'SelectKBestStrategy' object has no attribute 'fit_transform'
[2025-06-21 19:21:41,467] 195 Model_Tune_Evaluate.py - CRITICAL - Fatal error in classifier tuning pipeline.
[2025-06-21 19:21:41,469] 90 __init__.py - CRITICAL - Unhandled Exception
Traceback (most recent call last):
  File "D:\ml_churn_prediction_mlops\src\Model_Tune_Evaluate.py", line 128, in run_grid_search
    X_selected = selector.fit_transform(X_resampled, y_resampled)
AttributeError: 'SelectKBestStrategy' object has no attribute 'fit_transform'

During handling of the above exception, another exception occurred:

Traceback (most recent call last):
  File "D:\ml_churn_prediction_mlops\src\Model_Tune_Evaluate.py", line 191, in execute_model_tune_evaluate
    tuner.run_grid_search()
  File "d:\ml_churn_prediction_mlops\Common_Utils\__init__.py", line 105, in wrapper
    result = func(*args, **kwargs)
  File "D:\ml_churn_prediction_mlops\src\Model_Tune_Evaluate.py", line 163, in run_grid_search
    raise CustomException(e,sys)
Common_Utils.CustomException: Error in script: [D:\ml_churn_prediction_mlops\src\Model_Tune_Evaluate.py] at line [128] - Message: ['SelectKBestStrategy' object has no attribute 'fit_transform']

During handling of the above exception, another exception occurred:

Traceback (most recent call last):
  File "D:\ml_churn_prediction_mlops\src\Model_Tune_Evaluate.py", line 200, in <module>
    execute_model_tune_evaluate()
  File "d:\ml_churn_prediction_mlops\Common_Utils\__init__.py", line 105, in wrapper
    result = func(*args, **kwargs)
  File "D:\ml_churn_prediction_mlops\src\Model_Tune_Evaluate.py", line 196, in execute_model_tune_evaluate
    raise CustomException(e,sys)
Common_Utils.CustomException: Error in script: [D:\ml_churn_prediction_mlops\src\Model_Tune_Evaluate.py] at line [191] - Message: [Error in script: [D:\ml_churn_prediction_mlops\src\Model_Tune_Evaluate.py] at line [128] - Message: ['SelectKBestStrategy' object has no attribute 'fit_transform']]
