[2025-06-23 13:06:04,384] 127 __init__.py - INFO - Loaded config from Config_Yaml/config_path.yaml
[2025-06-23 13:06:04,384] 99 Experiment_Tracking_Prediction.py - INFO - MLflow tracking URI set to: https://dagshub.com/anp102618/ml_churn_prediction_mlops.mlflow
[2025-06-23 13:06:04,420] 127 __init__.py - INFO - Loaded config from Config_Yaml\tuned_models.yaml
[2025-06-23 13:06:04,420] 115 Experiment_Tracking_Prediction.py - INFO - Using model: XGBClassifier with params: {'colsample_bytree': 1.0, 'gamma': 0, 'learning_rate': 0.1, 'max_depth': 6, 'n_estimators': 200, 'reg_alpha': 0.1, 'reg_lambda': 1.5, 'subsample': 0.8, 'tree_method': 'hist'}
[2025-06-23 13:06:08,493] 206 Experiment_Tracking_Prediction.py - ERROR - [UnhandledException] API request to endpoint /api/2.0/mlflow/runs/create failed with error code 403 != 200. Response body: ''
Traceback (most recent call last):
  File "D:\ml_churn_prediction_mlops\src\Experiment_Tracking_Prediction.py", line 157, in execute_mlflow_steps
    with mlflow.start_run(run_name=run_name) as run:
  File "C:\Users\prasa\anaconda3\envs\mlp-env\lib\site-packages\mlflow\tracking\fluent.py", line 474, in start_run
    active_run_obj = client.create_run(
  File "C:\Users\prasa\anaconda3\envs\mlp-env\lib\site-packages\mlflow\tracking\client.py", line 434, in create_run
    return self._tracking_client.create_run(experiment_id, start_time, tags, run_name)
  File "C:\Users\prasa\anaconda3\envs\mlp-env\lib\site-packages\mlflow\tracking\_tracking_service\client.py", line 161, in create_run
    return self.store.create_run(
  File "C:\Users\prasa\anaconda3\envs\mlp-env\lib\site-packages\mlflow\store\tracking\rest_store.py", line 272, in create_run
    response_proto = self._call_endpoint(CreateRun, req_body)
  File "C:\Users\prasa\anaconda3\envs\mlp-env\lib\site-packages\mlflow\store\tracking\rest_store.py", line 135, in _call_endpoint
    return call_endpoint(
  File "C:\Users\prasa\anaconda3\envs\mlp-env\lib\site-packages\mlflow\utils\rest_utils.py", line 590, in call_endpoint
    response = verify_rest_response(response, endpoint)
  File "C:\Users\prasa\anaconda3\envs\mlp-env\lib\site-packages\mlflow\utils\rest_utils.py", line 310, in verify_rest_response
    raise MlflowException(
mlflow.exceptions.MlflowException: API request to endpoint /api/2.0/mlflow/runs/create failed with error code 403 != 200. Response body: ''
