[2025-06-22 12:53:57,981] 123 __init__.py - INFO - Loaded config from Config_Yaml/config_path.yaml
[2025-06-22 12:53:57,984] 123 __init__.py - INFO - Loaded config from Config_Yaml/config_path.yaml
[2025-06-22 12:53:57,986] 100 __init__.py - INFO - Running 'execute_data_preprocessing'...
[2025-06-22 12:53:57,986] 135 Data_Preprocessing.py - INFO - Starting Data Preprocessing...
[2025-06-22 12:53:57,986] 36 sqlite_handler.py - INFO - Connected to SQLite DB at Data\data.db
[2025-06-22 12:53:58,154] 96 sqlite_handler.py - INFO - Executed read query. Rows fetched: 10127
[2025-06-22 12:53:58,545] 217 Data_Preprocessing.py - ERROR - Preprocessing pipeline failed.
Traceback (most recent call last):
  File "D:\ml_churn_prediction_mlops\src\Data_Preprocessing.py", line 173, in execute_data_preprocessing
    y_train = y_train_impute.map({"Existing Customer": 0, "Attrited Customer": 1}).astype(int)
  File "C:\Users\prasa\anaconda3\envs\mlp-env\lib\site-packages\pandas\core\frame.py", line 10470, in map
    func = functools.partial(func, **kwargs)
TypeError: the first argument must be callable
[2025-06-22 12:53:58,561] 90 __init__.py - CRITICAL - Unhandled Exception
Traceback (most recent call last):
  File "D:\ml_churn_prediction_mlops\src\Data_Preprocessing.py", line 173, in execute_data_preprocessing
    y_train = y_train_impute.map({"Existing Customer": 0, "Attrited Customer": 1}).astype(int)
  File "C:\Users\prasa\anaconda3\envs\mlp-env\lib\site-packages\pandas\core\frame.py", line 10470, in map
    func = functools.partial(func, **kwargs)
TypeError: the first argument must be callable

During handling of the above exception, another exception occurred:

Traceback (most recent call last):
  File "D:\ml_churn_prediction_mlops\src\Data_Preprocessing.py", line 222, in <module>
    execute_data_preprocessing()
  File "d:\ml_churn_prediction_mlops\Common_Utils\__init__.py", line 105, in wrapper
    result = func(*args, **kwargs)
  File "D:\ml_churn_prediction_mlops\src\Data_Preprocessing.py", line 218, in execute_data_preprocessing
    raise CustomException(e, sys)
Common_Utils.CustomException: Error in script: [D:\ml_churn_prediction_mlops\src\Data_Preprocessing.py] at line [173] - Message: [the first argument must be callable]
